===== MAIgnus_CAIrlsen Started at Sat 05/03/2025 17:30:52.79  ===== 
Running MAIgnus_CAIrlsen chess analysis bot... 
[2025-05-03 17:30:56.261151] [ROCKET] Starting MAIgnus_CAIrlsen full workflow...
[2025-05-03 17:30:56.262660] [INBOX] Checking for new games on Chess.com...
Traceback (most recent call last):
  File "C:\Users\seanr\AppData\Local\Programs\Python\Python313\Lib\site-packages\urllib3\connection.py", line 198, in _new_conn
    sock = connection.create_connection(
        (self._dns_host, self.port),
    ...<2 lines>...
        socket_options=self.socket_options,
    )
  File "C:\Users\seanr\AppData\Local\Programs\Python\Python313\Lib\site-packages\urllib3\util\connection.py", line 60, in create_connection
    for res in socket.getaddrinfo(host, port, family, socket.SOCK_STREAM):
               ~~~~~~~~~~~~~~~~~~^^^^^^^^^^^^^^^^^^^^^^^^^^^^^^^^^^^^^^^^
  File "C:\Users\seanr\AppData\Local\Programs\Python\Python313\Lib\socket.py", line 977, in getaddrinfo
    for res in _socket.getaddrinfo(host, port, family, type, proto, flags):
               ~~~~~~~~~~~~~~~~~~~^^^^^^^^^^^^^^^^^^^^^^^^^^^^^^^^^^^^^^^^
socket.gaierror: [Errno 11001] getaddrinfo failed

The above exception was the direct cause of the following exception:

Traceback (most recent call last):
  File "C:\Users\seanr\AppData\Local\Programs\Python\Python313\Lib\site-packages\urllib3\connectionpool.py", line 787, in urlopen
    response = self._make_request(
        conn,
    ...<10 lines>...
        **response_kw,
    )
  File "C:\Users\seanr\AppData\Local\Programs\Python\Python313\Lib\site-packages\urllib3\connectionpool.py", line 488, in _make_request
    raise new_e
  File "C:\Users\seanr\AppData\Local\Programs\Python\Python313\Lib\site-packages\urllib3\connectionpool.py", line 464, in _make_request
    self._validate_conn(conn)
    ~~~~~~~~~~~~~~~~~~~^^^^^^
  File "C:\Users\seanr\AppData\Local\Programs\Python\Python313\Lib\site-packages\urllib3\connectionpool.py", line 1093, in _validate_conn
    conn.connect()
    ~~~~~~~~~~~~^^
  File "C:\Users\seanr\AppData\Local\Programs\Python\Python313\Lib\site-packages\urllib3\connection.py", line 704, in connect
    self.sock = sock = self._new_conn()
                       ~~~~~~~~~~~~~~^^
  File "C:\Users\seanr\AppData\Local\Programs\Python\Python313\Lib\site-packages\urllib3\connection.py", line 205, in _new_conn
    raise NameResolutionError(self.host, self, e) from e
urllib3.exceptions.NameResolutionError: <urllib3.connection.HTTPSConnection object at 0x000002517E5906E0>: Failed to resolve 'api.chess.com' ([Errno 11001] getaddrinfo failed)

The above exception was the direct cause of the following exception:

Traceback (most recent call last):
  File "C:\Users\seanr\AppData\Local\Programs\Python\Python313\Lib\site-packages\requests\adapters.py", line 667, in send
    resp = conn.urlopen(
        method=request.method,
    ...<9 lines>...
        chunked=chunked,
    )
  File "C:\Users\seanr\AppData\Local\Programs\Python\Python313\Lib\site-packages\urllib3\connectionpool.py", line 841, in urlopen
    retries = retries.increment(
        method, url, error=new_e, _pool=self, _stacktrace=sys.exc_info()[2]
    )
  File "C:\Users\seanr\AppData\Local\Programs\Python\Python313\Lib\site-packages\urllib3\util\retry.py", line 519, in increment
    raise MaxRetryError(_pool, url, reason) from reason  # type: ignore[arg-type]
    ^^^^^^^^^^^^^^^^^^^^^^^^^^^^^^^^^^^^^^^^^^^^^^^^^^^
urllib3.exceptions.MaxRetryError: HTTPSConnectionPool(host='api.chess.com', port=443): Max retries exceeded with url: /pub/player/seanr87/games/archives (Caused by NameResolutionError("<urllib3.connection.HTTPSConnection object at 0x000002517E5906E0>: Failed to resolve 'api.chess.com' ([Errno 11001] getaddrinfo failed)"))

During handling of the above exception, another exception occurred:

Traceback (most recent call last):
  File "C:\Users\seanr\MAIgnus_CAIrlsen\src\maignus_bot.py", line 69, in <module>
    main()
    ~~~~^^
  File "C:\Users\seanr\MAIgnus_CAIrlsen\src\maignus_bot.py", line 40, in main
    new_games = fetch_and_save_pgns()
  File "C:\Users\seanr\MAIgnus_CAIrlsen\src\chess_api.py", line 65, in fetch_and_save_pgns
    games = get_games_from_latest_archive(username)
  File "C:\Users\seanr\MAIgnus_CAIrlsen\src\chess_api.py", line 46, in get_games_from_latest_archive
    archives = get_archives(username)
  File "C:\Users\seanr\MAIgnus_CAIrlsen\src\chess_api.py", line 34, in get_archives
    response = requests.get(url, headers=CHESS_API_HEADERS)
  File "C:\Users\seanr\AppData\Local\Programs\Python\Python313\Lib\site-packages\requests\api.py", line 73, in get
    return request("get", url, params=params, **kwargs)
  File "C:\Users\seanr\AppData\Local\Programs\Python\Python313\Lib\site-packages\requests\api.py", line 59, in request
    return session.request(method=method, url=url, **kwargs)
           ~~~~~~~~~~~~~~~^^^^^^^^^^^^^^^^^^^^^^^^^^^^^^^^^^
  File "C:\Users\seanr\AppData\Local\Programs\Python\Python313\Lib\site-packages\requests\sessions.py", line 589, in request
    resp = self.send(prep, **send_kwargs)
  File "C:\Users\seanr\AppData\Local\Programs\Python\Python313\Lib\site-packages\requests\sessions.py", line 703, in send
    r = adapter.send(request, **kwargs)
  File "C:\Users\seanr\AppData\Local\Programs\Python\Python313\Lib\site-packages\requests\adapters.py", line 700, in send
    raise ConnectionError(e, request=request)
requests.exceptions.ConnectionError: HTTPSConnectionPool(host='api.chess.com', port=443): Max retries exceeded with url: /pub/player/seanr87/games/archives (Caused by NameResolutionError("<urllib3.connection.HTTPSConnection object at 0x000002517E5906E0>: Failed to resolve 'api.chess.com' ([Errno 11001] getaddrinfo failed)"))
===== MAIgnus_CAIrlsen Completed at Sat 05/03/2025 17:30:56.57 ===== 
